<?xml version="1.0" ?>
<!-- =================================================================================== -->
<!-- |    This document was autogenerated by xacro from cmbot.urdf.xacro               | -->
<!-- |    EDITING THIS FILE BY HAND IS NOT RECOMMENDED                                 | -->
<!-- =================================================================================== -->
<robot name="cmbot">
  <!-- ROS 2 Control -->
  <gazebo>
    <plugin filename="ign_ros2_control-system" name="ign_ros2_control::IgnitionROS2ControlPlugin">
      <parameters>/home/combatant/cmbot_ws/install/cmbot_controller/share/cmbot_controller/config/cmbot_controllers.yaml</parameters>
    </plugin>
  </gazebo>
  <ros2_control name="RobotSystem" type="system">
    <hardware>
      <plugin>ign_ros2_control/IgnitionSystem</plugin>
    </hardware>
    <joint name="joint_5">
      <param name="mimic">joint_4</param>
      <param name="multiplier">-1</param>
    </joint>
    <joint name="joint_1">
      <command_interface name="position">
        <param name="min">-1.570796326795</param>
        <param name="max">1.570796326795</param>
      </command_interface>
      <state_interface name="position"/>
    </joint>
    <joint name="joint_2">
      <command_interface name="position">
        <param name="min">-1.570796326795</param>
        <param name="max">1.570796326795</param>
      </command_interface>
      <state_interface name="position"/>
    </joint>
    <joint name="joint_3">
      <command_interface name="position">
        <param name="min">-1.570796326795</param>
        <param name="max">1.570796326795</param>
      </command_interface>
      <state_interface name="position"/>
    </joint>
    <joint name="joint_4">
      <command_interface name="position">
        <param name="min">-1.570796326795</param>
        <param name="max">0.0</param>
      </command_interface>
      <state_interface name="position"/>
    </joint>
  </ros2_control>
  <link name="world"/>
  <link name="base_link">
    <inertial>
      <mass value="1"/>
      <inertia ixx="1.0" ixy="0.0" ixz="0.0" iyy="1.0" iyz="0.0" izz="1.0"/>
    </inertial>
    <visual>
      <origin rpy="0 0 0 " xyz="-0.5 -0.5 0 "/>
      <geometry>
        <mesh filename="package://cmbot_description/meshes/basement.STL" scale="0.01 0.01 0.01"/>
      </geometry>
    </visual>
    <collision>
      <origin rpy="0 0 0 " xyz="-0.5 -0.5 0 "/>
      <geometry>
        <mesh filename="package://cmbot_description/meshes/basement.STL" scale="0.01 0.01 0.01"/>
      </geometry>
    </collision>
  </link>
  <joint name="virtual_joint" type="fixed">
    <parent link="world"/>
    <child link="base_link"/>
    <origin rpy="0 0 0 " xyz="0 0 0 "/>
  </joint>
  <link name="base_plate">
    <inertial>
      <mass value="0.1"/>
      <inertia ixx="1.0" ixy="0.0" ixz="0.0" iyy="1.0" iyz="0.0" izz="1.0"/>
    </inertial>
    <visual>
      <origin rpy="0 0 0" xyz="-0.39 -0.39 -0.56"/>
      <geometry>
        <mesh filename="package://cmbot_description/meshes/base_plate.STL" scale="0.01 0.01 0.01"/>
      </geometry>
    </visual>
    <collision>
      <origin rpy="0 0 0" xyz="-0.39 -0.39 -0.56"/>
      <geometry>
        <mesh filename="package://cmbot_description/meshes/base_plate.STL" scale="0.01 0.01 0.01"/>
      </geometry>
    </collision>
  </link>
  <joint name="joint_1" type="revolute">
    <parent link="base_link"/>
    <child link="base_plate"/>
    <axis xyz="0 0 1"/>
    <origin rpy="0 0 0 " xyz="0 0 0.307 "/>
    <limit effort="30.0" lower="-1.570795" upper="1.570795" velocity="10.0"/>
  </joint>
  <link name="forward_drive_arm">
    <inertial>
      <mass value="0.1"/>
      <inertia ixx="1.0" ixy="0.0" ixz="0.0" iyy="1.0" iyz="0.0" izz="1.0"/>
    </inertial>
    <visual>
      <origin rpy="0 -1.570795 1.570795" xyz="0.19 0.06 -0.08"/>
      <geometry>
        <mesh filename="package://cmbot_description/meshes/forward_drive_arm.STL" scale="0.01 0.01 0.01"/>
      </geometry>
    </visual>
    <collision>
      <origin rpy="0 -1.570795 1.570795" xyz="0.19 0.06 -0.08"/>
      <geometry>
        <mesh filename="package://cmbot_description/meshes/forward_drive_arm.STL" scale="0.01 0.01 0.01"/>
      </geometry>
    </collision>
  </link>
  <joint name="joint_2" type="revolute">
    <parent link="base_plate"/>
    <child link="forward_drive_arm"/>
    <axis xyz="1 0 0"/>
    <origin rpy="0 0 0" xyz="-0.02 0 0.35"/>
    <limit effort="30.0" lower="-1.570795" upper="1.570795" velocity="10.0"/>
  </joint>
  <link name="horizontal_arm">
    <inertial>
      <mass value="0.1"/>
      <inertia ixx="1.0" ixy="0.0" ixz="0.0" iyy="1.0" iyz="0.0" izz="1.0"/>
    </inertial>
    <visual>
      <origin rpy="1.570795 0 1.570795" xyz="-0.03 -0.4 -0.06"/>
      <geometry>
        <mesh filename="package://cmbot_description/meshes/horizontal_arm.STL" scale="0.01 0.01 0.01"/>
      </geometry>
    </visual>
    <collision>
      <origin rpy="1.570795 0 1.570795" xyz="-0.03 -0.4 -0.06"/>
      <geometry>
        <mesh filename="package://cmbot_description/meshes/horizontal_arm.STL" scale="0.01 0.01 0.01"/>
      </geometry>
    </collision>
  </link>
  <joint name="joint_3" type="revolute">
    <parent link="forward_drive_arm"/>
    <child link="horizontal_arm"/>
    <axis xyz="1 0 0"/>
    <origin rpy="0 0 0" xyz="0 0 0.8"/>
    <limit effort="30.0" lower="-1.570795" upper="1.570795" velocity="10.0"/>
  </joint>
  <link name="claw_support">
    <inertial>
      <mass value="0.05"/>
      <inertia ixx="1.0" ixy="0.0" ixz="0.0" iyy="1.0" iyz="0.0" izz="1.0"/>
    </inertial>
    <visual>
      <origin rpy="0 0 1.570795" xyz="0 -0.05 -0.15"/>
      <geometry>
        <mesh filename="package://cmbot_description/meshes/claw_support.STL" scale="0.01 0.01 0.01"/>
      </geometry>
    </visual>
    <collision>
      <origin rpy="0 0 1.570795" xyz="0 -0.05 -0.15"/>
      <geometry>
        <mesh filename="package://cmbot_description/meshes/claw_support.STL" scale="0.01 0.01 0.01"/>
      </geometry>
    </collision>
  </link>
  <joint name="horizontal_arm_to_claw_support" type="fixed">
    <parent link="horizontal_arm"/>
    <child link="claw_support"/>
    <origin rpy="0 0 0" xyz="0 0.82 0"/>
  </joint>
  <link name="right_gripper">
    <inertial>
      <mass value="0.01"/>
      <inertia ixx="1.0" ixy="0.0" ixz="0.0" iyy="1.0" iyz="0.0" izz="1.0"/>
    </inertial>
    <visual>
      <origin rpy="0 0 -1.570795" xyz="-0.1 0.5 -0.1"/>
      <geometry>
        <mesh filename="package://cmbot_description/meshes/right_finger.STL" scale="0.01 0.01 0.01"/>
      </geometry>
    </visual>
    <collision>
      <origin rpy="0 0 -1.570795" xyz="-0.1 0.5 -0.1"/>
      <geometry>
        <mesh filename="package://cmbot_description/meshes/right_finger.STL" scale="0.01 0.01 0.01"/>
      </geometry>
    </collision>
  </link>
  <link name="left_gripper">
    <inertial>
      <mass value="0.01"/>
      <inertia ixx="1.0" ixy="0.0" ixz="0.0" iyy="1.0" iyz="0.0" izz="1.0"/>
    </inertial>
    <visual>
      <origin rpy="0 0 -1.570795" xyz="-0.04 0.50 -0.1"/>
      <geometry>
        <mesh filename="package://cmbot_description/meshes/left_finger.STL" scale="0.01 0.01 0.01"/>
      </geometry>
    </visual>
    <collision>
      <origin rpy="0 0 -1.570795" xyz="-0.04 0.50 -0.1"/>
      <geometry>
        <mesh filename="package://cmbot_description/meshes/left_finger.STL" scale="0.01 0.01 0.01"/>
      </geometry>
    </collision>
  </link>
  <joint name="joint_4" type="revolute">
    <parent link="claw_support"/>
    <child link="right_gripper"/>
    <axis xyz="0 0 1"/>
    <origin rpy="0 0 0 " xyz="-0.04 0.13 -0.1"/>
    <limit effort="30.0" lower="-1.570795" upper="0.0" velocity="10.0"/>
  </joint>
  <joint name="joint_5" type="revolute">
    <parent link="claw_support"/>
    <child link="left_gripper"/>
    <axis xyz="0 0 1"/>
    <origin rpy="0 0 0" xyz="-0.22 0.13 -0.1"/>
    <mimic joint="joint_4" multiplier="-1"/>
    <limit effort="30.0" lower="0.0" upper="1.570795" velocity="10.0"/>
  </joint>
</robot>
